test_add_two_nagetive (Day10.Demo2_unittest_TestCase.TestMathMethod_add) ... ok
test_add_two_positive (Day10.Demo2_unittest_TestCase.TestMathMethod_add) ... ok
test_add_two_zero (Day10.Demo2_unittest_TestCase.TestMathMethod_add) ... FAIL

======================================================================
FAIL: test_add_two_zero (Day10.Demo2_unittest_TestCase.TestMathMethod_add)
----------------------------------------------------------------------
Traceback (most recent call last):
  File "D:\pythonWorkspace\Demo1\Day10\Demo2_unittest_TestCase.py", line 37, in test_add_two_zero
    self.assertEqual(1, result,msg="预期结果：{0}，结果：{1}".format(1,result))
AssertionError: 1 != 0 : 预期结果：1，结果：0

----------------------------------------------------------------------
Ran 3 tests in 0.001s

FAILED (failures=1)
